<?xml version="1.0" ?>
<!-- =================================================================================== -->
<!-- |    This document was autogenerated by xacro from m10ia.xacro                    | -->
<!-- |    EDITING THIS FILE BY HAND IS NOT RECOMMENDED                                 | -->
<!-- =================================================================================== -->
<robot name="fanuc" xmlns:xacro="http://ros.org/wiki/xacro">
  <link name="world" />
  <link name="base" />
  <link name="box">
      <inertial>
          <mass value="0.1" />
          <inertia ixx="0.03" iyy="0.03" izz="0.03" ixy="0.0" ixz="0.0" iyz="0.0" />
      </inertial>
      <visual>
          <origin rpy="0 0 0" xyz="0 0 0.75" />
          <geometry>
              <box size="1 1 1.5" />
          </geometry>
      </visual>
      <collision>
          <origin rpy="0 0 0" xyz="0 0 0.75" />
          <geometry>
              <box size="1 1 1.5" />
          </geometry>
      </collision>
  </link>
  <!-- links: main serial chain -->
  <link name="base_link">
    <visual>
      <origin xyz="0 0 0" rpy="0 0 0"/>
      <geometry>
        <mesh filename="package://r2000_description/meshes/visual/base_link.stl"/>
      </geometry>
    </visual>
    <collision>
      <origin xyz="0 0 0" rpy="0 0 0"/>
      <geometry>
        <mesh filename="package://r2000_description/meshes/collision/base_link.stl"/>
      </geometry>
    </collision>
    <inertial>
        <mass value="0.1" />
        <inertia ixx="0.03" iyy="0.03" izz="0.03" ixy="0.0" ixz="0.0" iyz="0.0" />
    </inertial>
  </link>
  <link name="link_1">
    <visual>
      <origin xyz="0 0 0" rpy="0 0 0"/>
      <geometry>
        <mesh filename="package://r2000_description/meshes/visual/link_1.stl"/>
      </geometry>
    </visual>
    <collision>
      <origin xyz="0 0 0" rpy="0 0 0"/>
      <geometry>
        <mesh filename="package://r2000_description/meshes/collision/link_1.stl"/>
      </geometry>
    </collision>
    <inertial>
        <mass value="0.1" />
        <inertia ixx="0.03" iyy="0.03" izz="0.03" ixy="0.0" ixz="0.0" iyz="0.0" />
    </inertial>
  </link>
  <link name="link_2">
    <visual>
      <origin xyz="0 0 0" rpy="0 0 0"/>
      <geometry>
        <mesh filename="package://r2000_description/meshes/visual/link_2.stl"/>
      </geometry>
    </visual>
    <collision>
      <origin xyz="0 0 0" rpy="0 0 0"/>
      <geometry>
        <mesh filename="package://r2000_description/meshes/collision/link_2.stl"/>
      </geometry>
    </collision>
    <inertial>
        <mass value="0.1" />
        <inertia ixx="0.03" iyy="0.03" izz="0.03" ixy="0.0" ixz="0.0" iyz="0.0" />
    </inertial>
  </link>
  <link name="link_3">
    <visual>
      <origin xyz="0 0 0" rpy="0 0 0"/>
      <geometry>
        <mesh filename="package://r2000_description/meshes/visual/link_3.stl"/>
      </geometry>
    </visual>
    <collision>
      <origin xyz="0 0 0" rpy="0 0 0"/>
      <geometry>
        <mesh filename="package://r2000_description/meshes/collision/link_3.stl"/>
      </geometry>
    </collision>
    <inertial>
        <mass value="0.1" />
        <inertia ixx="0.03" iyy="0.03" izz="0.03" ixy="0.0" ixz="0.0" iyz="0.0" />
    </inertial>
  </link>
  <link name="link_4">
    <visual>
      <origin xyz="0 0 0" rpy="0 0 0"/>
      <geometry>
        <mesh filename="package://r2000_description/meshes/visual/link_4.stl"/>
      </geometry>
    </visual>
    <collision>
      <origin xyz="0 0 0" rpy="0 0 0"/>
      <geometry>
        <mesh filename="package://r2000_description/meshes/collision/link_4.stl"/>
      </geometry>
    </collision>
    <inertial>
        <mass value="0.1" />
        <inertia ixx="0.03" iyy="0.03" izz="0.03" ixy="0.0" ixz="0.0" iyz="0.0" />
    </inertial>
  </link>
  <link name="link_5">
    <visual>
      <origin xyz="0 0 0" rpy="0 0 0"/>
      <geometry>
        <mesh filename="package://r2000_description/meshes/visual/link_5.stl"/>
      </geometry>
    </visual>
    <collision>
      <origin xyz="0 0 0" rpy="0 0 0"/>
      <geometry>
        <mesh filename="package://r2000_description/meshes/collision/link_5.stl"/>
      </geometry>
    </collision>
    <inertial>
        <mass value="0.1" />
        <inertia ixx="0.03" iyy="0.03" izz="0.03" ixy="0.0" ixz="0.0" iyz="0.0" />
    </inertial>
  </link>
  <link name="link_6">
    <visual>
      <origin xyz="0 0 0" rpy="0 0 0"/>
      <geometry>
        <mesh filename="package://r2000_description/meshes/visual/link_6.stl"/>
      </geometry>
    </visual>
    <collision>
      <origin xyz="0 0 0" rpy="0 0 0"/>
      <geometry>
        <mesh filename="package://r2000_description/meshes/collision/link_6.stl"/>
      </geometry>
    </collision>
    <inertial>
        <mass value="0.1" />
        <inertia ixx="0.03" iyy="0.03" izz="0.03" ixy="0.0" ixz="0.0" iyz="0.0" />
    </inertial>
  </link>

  <link name="tool0" />

      <!-- EEF links -->
  <link name="link_hand">
      <visual>
          <origin rpy="0 0 0" xyz="0 0 0" />
          <geometry>
              <box size="0.25 0.8 0.03"/>
          </geometry>
          <material name="">
              <color rgba="0.15 0.15 0.15 1.0" />
          </material>
      </visual>
      <collision>
          <origin rpy="0 0 0" xyz="0 0 0" />
          <geometry>
              <box size="0.25 0.8 0.03"/> <!--<box size="0.1 0.4 0.03"/>-->
          </geometry>
      </collision>
      
      <inertial>
          <mass value="0.01" />
          <inertia ixx="0.03" iyy="0.03" izz="0.03" ixy="0.0" ixz="0.0" iyz="0.0" />
      </inertial>
  </link>

  <link name="link_right_finger">
      <visual>
          <origin rpy="0 0 0" xyz="0 0 0" />
          <geometry>
              <box size="0.55 0.015 0.4"/> <!--<box size="0.09 0.01 0.1"/>-->
          </geometry>
          <material name="">
              <color rgba="0.15 0.15 0.15 1.0" />
          </material>
      </visual>
      <collision>
          <origin rpy="0 0 0" xyz="0 0 0" />
          <geometry>
              <box size="0.55 0.015 0.4"/>
          </geometry>
      </collision>
      
      <inertial>
          <mass value="0.01" />
          <inertia ixx="0.03" iyy="0.03" izz="0.03" ixy="0.0" ixz="0.0" iyz="0.0" />
      </inertial>
  </link>

  <link name="link_left_finger">
      <visual>
          <origin rpy="0 0 0" xyz="0 0 0" />
          <geometry>
              <box size="0.55 0.015 0.4"/>
          </geometry>
          <material name="">
              <color rgba="0.15 0.15 0.15 1.0" />
          </material>
      </visual>
      <collision>
          <origin rpy="0 0 0" xyz="0 0 0" />
          <geometry>
              <box size="0.55 0.015 0.4"/>
          </geometry>
      </collision>
      
      <inertial>
          <mass value="0.01" />
          <inertia ixx="0.03" iyy="0.03" izz="0.03" ixy="0.0" ixz="0.0" iyz="0.0" />
      </inertial>
  </link>


  <!-- Fixing robot to box & box to world -->
  <joint name="world_to_box=" type="fixed">
      <parent link="world"/>
      <child link="box"/>
  </joint> 
  <joint name="box_to_base_link=" type="fixed">
      <origin rpy="0 0 0" xyz="0 0 1.5" />
      <parent link="box"/>
      <child link="base_link"/>
  <dynamics damping="0.7" friction="1"/>
  </joint>

  <joint name="base_link-base" type="fixed">
      <origin rpy="0 0 0" xyz="0 0 0.450" />
      <parent link="base_link" />
      <child link="base" />
  <dynamics damping="0.7" friction="1"/>
  </joint>
  
  <!-- joints: main serial chain -->
  <joint name="joint_1" type="revolute">
    <origin xyz="0 0 0.670" rpy="0 0 0"/>
    <parent link="base_link"/>
    <child link="link_1"/> 
    <axis xyz="0 0 1"/>
    <limit lower="-3.15" upper="3.15" effort="1000" velocity="2.26893"/>
  <dynamics damping="0.7" friction="1"/> 
  </joint>
  <joint name="joint_2" type="revolute">
    <origin xyz="0.312 0 0" rpy="0 0 0"/>
    <parent link="link_1"/>
    <child link="link_2"/>
    <axis xyz="0 1 0"/>
    <limit lower="-1.0472" upper="1.32645" effort="1000" velocity="2.00713"/>
  <dynamics damping="0.7" friction="1"/> 
  </joint>
  <joint name="joint_3" type="revolute">
    <origin xyz="0 0 1.075" rpy="0 0 0"/>
    <parent link="link_2"/>
    <child link="link_3"/>
    <axis xyz="0 -1 0"/>
    <limit lower="-2.30383" upper="3.14159" effort="1000" velocity="2.18166"/>
  <dynamics damping="0.7" friction="1"/>
  </joint>
  <joint name="joint_4" type="revolute">
    <origin xyz="0 0 0.225" rpy="0 0 0"/>
    <parent link="link_3"/>
    <child link="link_4"/>
    <axis xyz="-1 0 0"/>
    <limit lower="-6.28319" upper="6.28319" effort="1000" velocity="3.14159"/>
  <dynamics damping="0.7" friction="1"/>
  </joint>
  <joint name="joint_5" type="revolute">
    <origin xyz="1.280 0 0" rpy="0 0 0"/>
    <parent link="link_4"/>
    <child link="link_5"/>
    <axis xyz="0 -1 0"/>
    <limit lower="-2.18166" upper="2.18166" effort="1000" velocity="3.14"/>
  <dynamics damping="0.7" friction="1"/>
  </joint>
  <joint name="joint_6" type="revolute">
    <origin xyz="0.215 0 0" rpy="0 0 0"/>
    <parent link="link_5"/>
    <child link="link_6"/>
    <axis xyz="-1 0 0"/>
    <limit lower="-6.28" upper="6.28" effort="1000" velocity="4.54"/>
  <dynamics damping="0.7" friction="1"/>
  </joint>

  <!-- ROS-Industrial 'tool0' frame: all-zeros tool frame -->    
  <joint name="link_6-tool0" type="fixed">
    <origin xyz="0 0 0" rpy="3.14 -1.57 0" />
    <parent link="link_6" />
    <child link="tool0" />
  <dynamics damping="0.7" friction="1"/>
  </joint>

  <!-- EEF joints -->
  <joint name="hand_joint" type="fixed">
    <parent link="tool0" />
    <child link="link_hand" />
    <origin rpy="0 0 0" xyz="0 0 0.015001" />
  <dynamics damping="0.7" friction="1"/>
  </joint>

  <joint name="right_finger_joint" type="prismatic">
    <parent link="link_hand" />
    <child link="link_right_finger" />
    <origin rpy="0 0 0" xyz="0 0.25 0.215001" />
    <axis xyz="0 -1 0" />
    <limit effort="1000.0" lower="0" upper="0.15" velocity="0.5"/>
  <dynamics damping="0.7" friction="1"/>
  </joint>

  <joint name="left_finger_joint" type="prismatic">
    <parent link="link_hand" />
    <child link="link_left_finger" />
    <origin rpy="0 0 0" xyz="0 -0.25 0.215001" />
    <axis xyz="0 -1 0" />
    <limit effort="1000.0" lower="-0.15" upper="0" velocity="0.5"/>
  <dynamics damping="0.7" friction="1"/>
  </joint>
  
  <!--joint name="world_to_base_link=" type="fixed">
      <parent link="world"/>
      <child link="base_link"/>
  </joint-->

  <!--joint name="box_to_base=" type="fixed">
      <origin rpy="0 0 0" xyz="0 0 0.5" />
      <parent link="box"/>
      <child link="base"/>
  </joint>-->

  <transmission name="trans_joint_1">
      <type>transmission_interface/SimpleTransmission</type>
      <joint name="joint_1">
          <hardwareInterface>hardware_interface/EffortJointInterface</hardwareInterface>
      </joint>
      <actuator name="joint_1_motor">
          <hardwareInterface>hardware_interface/EffortJointInterface</hardwareInterface>
          <mechanicalReduction>1</mechanicalReduction>
      </actuator>
  </transmission>
  <transmission name="trans_joint_2">
      <type>transmission_interface/SimpleTransmission</type>
      <joint name="joint_2">
          <hardwareInterface>hardware_interface/EffortJointInterface</hardwareInterface>
      </joint>
      <actuator name="joint_2_motor">
          <hardwareInterface>hardware_interface/EffortJointInterface</hardwareInterface>
          <mechanicalReduction>1</mechanicalReduction>
      </actuator>
  </transmission>
  <transmission name="trans_joint_3">
      <type>transmission_interface/SimpleTransmission</type>
      <joint name="joint_3">
          <hardwareInterface>hardware_interface/EffortJointInterface</hardwareInterface>
      </joint>
      <actuator name="joint_3_motor">
          <hardwareInterface>hardware_interface/EffortJointInterface</hardwareInterface>
          <mechanicalReduction>1</mechanicalReduction>
      </actuator>
  </transmission>
  <transmission name="trans_joint_4">
      <type>transmission_interface/SimpleTransmission</type>
      <joint name="joint_4">
          <hardwareInterface>hardware_interface/EffortJointInterface</hardwareInterface>
      </joint>
      <actuator name="joint_4_motor">
          <hardwareInterface>hardware_interface/EffortJointInterface</hardwareInterface>
          <mechanicalReduction>1</mechanicalReduction>
      </actuator>
  </transmission>
  <transmission name="trans_joint_5">
      <type>transmission_interface/SimpleTransmission</type>
      <joint name="joint_5">
          <hardwareInterface>hardware_interface/EffortJointInterface</hardwareInterface>
      </joint>
      <actuator name="joint_5_motor">
          <hardwareInterface>hardware_interface/EffortJointInterface</hardwareInterface>
          <mechanicalReduction>1</mechanicalReduction>
      </actuator>
  </transmission>
  <transmission name="trans_joint_6">
      <type>transmission_interface/SimpleTransmission</type>
      <joint name="joint_6">
          <hardwareInterface>hardware_interface/EffortJointInterface</hardwareInterface>
      </joint>
      <actuator name="joint_6_motor">
          <hardwareInterface>hardware_interface/EffortJointInterface</hardwareInterface>
          <mechanicalReduction>1</mechanicalReduction>
      </actuator>
  </transmission>
  <transmission name="trans_joint_right_finger">
      <type>transmission_interface/SimpleTransmission</type>
      <joint name="right_finger_joint">
          <hardwareInterface>hardware_interface/EffortJointInterface</hardwareInterface>
      </joint>
      <actuator name="right_finger_motor">
          <hardwareInterface>hardware_interface/EffortJointInterface</hardwareInterface>
          <mechanicalReduction>1</mechanicalReduction>
      </actuator>
  </transmission>
  <transmission name="trans_joint_left_finger">
      <type>transmission_interface/SimpleTransmission</type>
      <joint name="left_finger_joint">
          <hardwareInterface>hardware_interface/EffortJointInterface</hardwareInterface>
      </joint>
      <actuator name="left_finger_motor">
          <hardwareInterface>hardware_interface/EffortJointInterface</hardwareInterface>
          <mechanicalReduction>1</mechanicalReduction>
      </actuator>
  </transmission>
  <!-- Plugin to link Gazebo and ROS -->
  <gazebo>
      <plugin name="gazebo_ros_control" filename="libgazebo_ros_control.so">
          <robotNamespace>/</robotNamespace>
      </plugin>
  </gazebo>

  <!-- Box -->
  <gazebo reference="box">
    <material>Gazebo/Grey</material>
  </gazebo>

  <!-- Base Link -->
  <gazebo reference="base_link">
    <material>Gazebo/DarkGrey</material>
  </gazebo>

  <!-- Link1 -->
  <gazebo reference="link_1">
    <material>Gazebo/Yellow</material>
    <mu1>0.2</mu1>
    <mu2>0.2</mu2>
  </gazebo>

  <!-- Link2 -->
  <gazebo reference="link_2">
    <material>Gazebo/Yellow</material>
    <mu1>0.2</mu1>
    <mu2>0.2</mu2>
  </gazebo>

  <!-- Link3 -->
  <gazebo reference="link_3">
    <material>Gazebo/Yellow</material>
    <mu1>0.2</mu1>
    <mu2>0.2</mu2>
  </gazebo>

  <!-- Link4 -->
  <gazebo reference="link_4">
    <material>Gazebo/Yellow</material>
    <mu1>0.2</mu1>
    <mu2>0.2</mu2>
  </gazebo>

  <!-- Link5 -->
  <gazebo reference="link_5">
    <material>Gazebo/Yellow</material>
    <mu1>0.2</mu1>
    <mu2>0.2</mu2>
  </gazebo>

  <!-- Link6 -->
  <gazebo reference="link_6">
    <material>Gazebo/Yellow</material>
    <mu1>0.2</mu1>
    <mu2>0.2</mu2>
  </gazebo>

    <!-- Linkhand -->
  <gazebo reference="link_hand">
    <material>Gazebo/DarkGrey</material>
  </gazebo>

      <!-- Right Finger Link -->
  <gazebo reference="link_right_finger">
    <material>Gazebo/DarkGrey</material>
    <mu1>10</mu1>
    <mu2>10</mu2>
    <minDepth>0.001</minDepth>
    <maxVel>0.1</maxVel>
    <kp>100000000.0</kp>
    <kd>1000000.0</kd>
  </gazebo>

  <!-- Left Finger Link -->
  <gazebo reference="link_left_finger">
    <material>Gazebo/DarkGrey</material>
    <mu1>10</mu1>
    <mu2>10</mu2>
    <minDepth>0.001</minDepth>
    <maxVel>0.1</maxVel>
    <kp>100000000.0</kp>
    <kd>1000000.0</kd>
  </gazebo>

</robot>
