<?xml version="1.0"?>
<robot xmlns:xacro="http://wiki.ros.org/xacro">
  <xacro:include filename="$(find r2000_description)/urdf/common_materials.xacro"/>

  <xacro:macro name="fanuc_r2000ic165f" params="prefix">
    <!-- links: main serial chain -->
    <link name="world" />
    <link name="base_link">
      <visual>
        <origin xyz="0 0 0" rpy="0 0 0"/>
        <geometry>
          <mesh filename="package://r2000_description/meshes/visual/base_link.stl"/>
        </geometry>
        <xacro:material_fanuc_gray40 />
      </visual>
      <collision>
        <origin xyz="0 0 0" rpy="0 0 0"/>
        <geometry>
          <mesh filename="package://r2000_description/meshes/collision/base_link.stl"/>
        </geometry>
      </collision>
      <inertial>
          <mass value="0.1" />
          <inertia ixx="0.03" iyy="0.03" izz="0.03" ixy="0.0" ixz="0.0" iyz="0.0" />
      </inertial>
    </link>
    <link name="box">
      <inertial>
        <mass value="0.1" />
        <inertia ixx="0.03" iyy="0.03" izz="0.03" ixy="0.0" ixz="0.0" iyz="0.0" />
      </inertial>
      <visual>
        <origin rpy="0 0 0" xyz="0 0 0.25" />
        <geometry>
            <box size="0.2 0.15 0.5" />
        </geometry>
      </visual>
      <collision>
        <origin rpy="0 0 0" xyz="0 0 0.25" />
        <geometry>
            <box size="0.2 0.15 0.5" />
        </geometry>
      </collision>
      <inertial>
          <mass value="0.1" />
          <inertia ixx="0.03" iyy="0.03" izz="0.03" ixy="0.0" ixz="0.0" iyz="0.0" />
      </inertial>
    </link>
    <link name="link_1">
      <visual>
        <origin xyz="0 0 0" rpy="0 0 0"/>
        <geometry>
          <mesh filename="package://r2000_description/meshes/visual/link_1.stl"/>
        </geometry>
        <xacro:material_fanuc_yellow />
      </visual>
      <collision>
        <origin xyz="0 0 0" rpy="0 0 0"/>
        <geometry>
          <mesh filename="package://r2000_description/meshes/collision/link_1.stl"/>
        </geometry>
      </collision>
      <inertial>
          <mass value="0.1" />
          <inertia ixx="0.03" iyy="0.03" izz="0.03" ixy="0.0" ixz="0.0" iyz="0.0" />
      </inertial>
    </link>
    <link name="link_2">
      <visual>
        <origin xyz="0 0 0" rpy="0 0 0"/>
        <geometry>
          <mesh filename="package://r2000_description/meshes/visual/link_2.stl"/>
        </geometry>
        <xacro:material_fanuc_yellow />
      </visual>
      <collision>
        <origin xyz="0 0 0" rpy="0 0 0"/>
        <geometry>
          <mesh filename="package://r2000_description/meshes/collision/link_2.stl"/>
        </geometry>
      </collision>
      <inertial>
          <mass value="0.1" />
          <inertia ixx="0.03" iyy="0.03" izz="0.03" ixy="0.0" ixz="0.0" iyz="0.0" />
      </inertial>
    </link>
    <link name="link_3">
      <visual>
        <origin xyz="0 0 0" rpy="0 0 0"/>
        <geometry>
          <mesh filename="package://r2000_description/meshes/visual/link_3.stl"/>
        </geometry>
        <xacro:material_fanuc_yellow />
      </visual>
      <collision>
        <origin xyz="0 0 0" rpy="0 0 0"/>
        <geometry>
          <mesh filename="package://r2000_description/meshes/collision/link_3.stl"/>
        </geometry>
      </collision><link name="world" />
      <inertial>
          <mass value="0.1" />
          <inertia ixx="0.03" iyy="0.03" izz="0.03" ixy="0.0" ixz="0.0" iyz="0.0" />
      </inertial>
    </link>
    <link name="link_4">
      <visual>
        <origin xyz="0 0 0" rpy="0 0 0"/>
        <geometry>
          <mesh filename="package://r2000_description/meshes/visual/link_4.stl"/>
        </geometry>
        <xacro:material_fanuc_yellow />
      </visual>
      <collision>
        <origin xyz="0 0 0" rpy="0 0 0"/>
        <geometry>
          <mesh filename="package://r2000_description/meshes/collision/link_4.stl"/>
        </geometry>
      </collision>
      <inertial>
          <mass value="0.1" />
          <inertia ixx="0.03" iyy="0.03" izz="0.03" ixy="0.0" ixz="0.0" iyz="0.0" />
      </inertial>
    </link>
    <link name="link_5">
      <visual>
        <origin xyz="0 0 0" rpy="0 0 0"/>
        <geometry>
          <mesh filename="package://r2000_description/meshes/visual/link_5.stl"/>
        </geometry>
        <xacro:material_fanuc_yellow />
      </visual>
      <collision>
        <origin xyz="0 0 0" rpy="0 0 0"/>
        <geometry>
          <mesh filename="package://r2000_description/meshes/collision/link_5.stl"/>
        </geometry>
      </collision>
      <inertial>
          <mass value="0.1" />
          <inertia ixx="0.03" iyy="0.03" izz="0.03" ixy="0.0" ixz="0.0" iyz="0.0" />
      </inertial>
    </link>
    <link name="link_6">
      <visual>
        <origin xyz="0 0 0" rpy="0 0 0"/>
        <geometry>
          <mesh filename="package://r2000_description/meshes/visual/link_6.stl"/>
        </geometry>
        <xacro:material_fanuc_black />
      </visual>
      <collision>
        <origin xyz="0 0 0" rpy="0 0 0"/>
        <geometry>
          <mesh filename="package://r2000_description/meshes/collision/link_6.stl"/>
        </geometry>
      </collision>
      <inertial>
          <mass value="0.1" />
          <inertia ixx="0.03" iyy="0.03" izz="0.03" ixy="0.0" ixz="0.0" iyz="0.0" />
      </inertial>
    </link>

    <!-- EEF links -->
    <link name="link_hand">
        <visual>
            <origin rpy="0 0 0" xyz="0 0 0" />
            <geometry>
                <box size="0.1 0.4 0.03"/>
            </geometry>
            <material name="">
                <color rgba="0.15 0.15 0.15 1.0" />
            </material>
        </visual>
        <collision>
            <origin rpy="0 0 0" xyz="0 0 0" />
            <geometry>
                <box size="0.1 0.4 0.03"/>
            </geometry>
        </collision>
        
        <inertial>
            <mass value="0.01" />
            <inertia ixx="0.03" iyy="0.03" izz="0.03" ixy="0.0" ixz="0.0" iyz="0.0" />
        </inertial>
    </link>

    <link name="link_right_finger">
        <visual>
            <origin rpy="0 0 0" xyz="0 0 0" />
            <geometry>
                <box size="0.09 0.01 0.1"/>
            </geometry>
            <material name="">
                <color rgba="0.15 0.15 0.15 1.0" />
            </material>
        </visual>
        <collision>
            <origin rpy="0 0 0" xyz="0 0 0" />
            <geometry>
                <box size="0.09 0.01 0.1"/>
            </geometry>
        </collision>
        
        <inertial>
            <mass value="0.01" />
            <inertia ixx="0.03" iyy="0.03" izz="0.03" ixy="0.0" ixz="0.0" iyz="0.0" />
        </inertial>
    </link>

    <link name="link_left_finger">
        <visual>
            <origin rpy="0 0 0" xyz="0 0 0" />
            <geometry>
                <box size="0.09 0.01 0.1"/>
            </geometry>
            <material name="">
                <color rgba="0.15 0.15 0.15 1.0" />
            </material>
        </visual>
        <collision>
            <origin rpy="0 0 0" xyz="0 0 0" />
            <geometry>
                <box size="0.09 0.01 0.1"/>
            </geometry>
        </collision>
        
        <inertial>
            <mass value="0.01" />
            <inertia ixx="0.03" iyy="0.03" izz="0.03" ixy="0.0" ixz="0.0" iyz="0.0" />
        </inertial>
    </link>

    <link name="tool0" />

    <!-- joints: main serial chain -->
    <joint name="joint_1" type="revolute">
      <origin xyz="0 0 0.670" rpy="0 0 0"/>
      <parent link="base_link"/>
      <child link="link_1"/> 
      <axis xyz="0 0 1"/>
      <limit lower="${radians(-185)}" upper="${radians(185)}" effort="1000" velocity="${radians(130)}"/>
    <dynamics damping="0.7" friction="1"/> 
    </joint>
    <joint name="joint_2" type="revolute">
      <origin xyz="0.312 0 0" rpy="0 0 0"/>
      <parent link="link_1"/>
      <child link="link_2"/>
      <axis xyz="0 1 0"/>
      <limit lower="${radians(-60)}" upper="${radians(76)}" effort="1000" velocity="${radians(115)}"/>
    <dynamics damping="0.7" friction="1"/> 
    </joint>
    <joint name="joint_3" type="revolute">
      <origin xyz="0 0 1.075" rpy="0 0 0"/>
      <parent link="link_2"/>
      <child link="link_3"/>
      <axis xyz="0 -1 0"/>
      <limit lower="${radians(-132)}" upper="${radians(180)}" effort="1000" velocity="${radians(125)}"/>
    <dynamics damping="0.7" friction="1"/>
    </joint>
    <joint name="joint_4" type="revolute">
      <origin xyz="0 0 0.225" rpy="0 0 0"/>
      <parent link="link_3"/>
      <child link="link_4"/>
      <axis xyz="-1 0 0"/>
      <limit lower="${radians(-360)}" upper="${radians(360)}" effort="1000" velocity="${radians(180)}"/>
    <dynamics damping="0.7" friction="1"/>
    </joint>
    <joint name="joint_5" type="revolute">
      <origin xyz="1.280 0 0" rpy="0 0 0"/>
      <parent link="link_4"/>
      <child link="link_5"/>
      <axis xyz="0 -1 0"/>
      <limit lower="${radians(-125)}" upper="${radians(125)}" effort="1000" velocity="${radians(180)}"/>
    <dynamics damping="0.7" friction="1"/>
    </joint>
    <joint name="joint_6" type="revolute">
      <origin xyz="0.215 0 0" rpy="0 0 0"/>
      <parent link="link_5"/>
      <child link="link_6"/>
      <axis xyz="-1 0 0"/>
      <limit lower="${radians(-360)}" upper="${radians(360)}" effort="1000" velocity="${radians(260)}"/>
    <dynamics damping="0.7" friction="1"/>
    </joint>

    <!-- ROS-Industrial 'tool0' frame: all-zeros tool frame -->    
    <joint name="link_6-tool0" type="fixed">
      <origin xyz="0 0 0" rpy="${pi} ${-pi/2.0} 0" />
      <parent link="link_6" />
      <child link="tool0" />
    <dynamics damping="0.7" friction="1"/>
    </joint>

    <!-- EEF joints -->
    <joint name="hand_joint" type="fixed">
      <parent link="tool0" />
      <child link="link_hand" />
      <origin rpy="0 0 0" xyz="0 0 0.015001" />
    <dynamics damping="0.7" friction="1"/>
    </joint>

    <joint name="right_finger_joint" type="prismatic">
      <parent link="link_hand" />
      <child link="link_right_finger" />
      <origin rpy="0 0 0" xyz="0 0.15 0.0650001" />
      <axis xyz="0 -1 0" />
      <limit effort="1000.0" lower="0" upper="0.38" velocity="0.5"/>
    <dynamics damping="0.7" friction="1"/>
    </joint>

    <joint name="left_finger_joint" type="prismatic">
      <parent link="link_hand" />
      <child link="link_left_finger" />
      <origin rpy="0 0 0" xyz="0 -0.15 0.0650001" />
      <axis xyz="0 -1 0" />
      <limit effort="1000.0" lower="-0.38" upper="0" velocity="0.5"/>
    <dynamics damping="0.7" friction="1"/>
    </joint>

    
    
    <!-- ROS-Industrial 'base' frame: base_link to Fanuc World Coordinates transform -->
    <link name="base" />
    <joint name="base_link-base" type="fixed">
      <origin xyz="0 0 0.670" rpy="0 0 0"/>
      <parent link="base_link"/>
      <child link="base"/>
    <dynamics damping="0.7" friction="1"/>
    </joint>

    <!-- ROS-Industrial 'flange' frame: attachment point for EEF models 
    <link name="flange" />
    <joint name="joint_6-flange" type="fixed">
      <origin xyz="0 0 0" rpy="0 0 0" />
      <parent link="link_6" />
      <child link="flange" />
    </joint> -->



    <!-- Fixing robot to box & box to world (gazebo requires world connection)-->
    <joint name="world_to_box=" type="fixed">
      <parent link="world"/>
      <child link="box"/>
    </joint> 
    <joint name="box_to_base_link=" type="fixed">
      <origin rpy="0 0 0" xyz="0 0 0.5" />
      <parent link="box"/>
      <child link="base_link"/>
    <dynamics damping="0.7" friction="1"/>
    </joint>

    <transmission name="trans_joint_1">
        <type>transmission_interface/SimpleTransmission</type>
        <joint name="joint_1">
            <hardwareInterface>hardware_interface/EffortJointInterface</hardwareInterface>
        </joint>
        <actuator name="joint_1_motor">
            <hardwareInterface>hardware_interface/EffortJointInterface</hardwareInterface>
            <mechanicalReduction>1</mechanicalReduction>
        </actuator>
    </transmission>
    <transmission name="trans_joint_2">
        <type>transmission_interface/SimpleTransmission</type>
        <joint name="joint_2">
            <hardwareInterface>hardware_interface/EffortJointInterface</hardwareInterface>
        </joint>
        <actuator name="joint_2_motor">
            <hardwareInterface>hardware_interface/EffortJointInterface</hardwareInterface>
            <mechanicalReduction>1</mechanicalReduction>
        </actuator>
    </transmission>
    <transmission name="trans_joint_3">
        <type>transmission_interface/SimpleTransmission</type>
        <joint name="joint_3">
            <hardwareInterface>hardware_interface/EffortJointInterface</hardwareInterface>
        </joint>
        <actuator name="joint_3_motor">
            <hardwareInterface>hardware_interface/EffortJointInterface</hardwareInterface>
            <mechanicalReduction>1</mechanicalReduction>
        </actuator>
    </transmission>
    <transmission name="trans_joint_4">
        <type>transmission_interface/SimpleTransmission</type>
        <joint name="joint_4">
            <hardwareInterface>hardware_interface/EffortJointInterface</hardwareInterface>
        </joint>
        <actuator name="joint_4_motor">
            <hardwareInterface>hardware_interface/EffortJointInterface</hardwareInterface>
            <mechanicalReduction>1</mechanicalReduction>
        </actuator>
    </transmission>
    <transmission name="trans_joint_5">
        <type>transmission_interface/SimpleTransmission</type>
        <joint name="joint_5">
            <hardwareInterface>hardware_interface/EffortJointInterface</hardwareInterface>
        </joint>
        <actuator name="joint_5_motor">
            <hardwareInterface>hardware_interface/EffortJointInterface</hardwareInterface>
            <mechanicalReduction>1</mechanicalReduction>
        </actuator>
    </transmission>
    <transmission name="trans_joint_6">
        <type>transmission_interface/SimpleTransmission</type>
        <joint name="joint_6">
            <hardwareInterface>hardware_interface/EffortJointInterface</hardwareInterface>
        </joint>
        <actuator name="joint_6_motor">
            <hardwareInterface>hardware_interface/EffortJointInterface</hardwareInterface>
            <mechanicalReduction>1</mechanicalReduction>
        </actuator>
    </transmission>
    <transmission name="trans_joint_right_finger">
        <type>transmission_interface/SimpleTransmission</type>
        <joint name="right_finger_joint">
            <hardwareInterface>hardware_interface/EffortJointInterface</hardwareInterface>
        </joint>
        <actuator name="right_finger_motor">
            <hardwareInterface>hardware_interface/EffortJointInterface</hardwareInterface>
            <mechanicalReduction>1</mechanicalReduction>
        </actuator>
    </transmission>
    <transmission name="trans_joint_left_finger">
        <type>transmission_interface/SimpleTransmission</type>
        <joint name="left_finger_joint">
            <hardwareInterface>hardware_interface/EffortJointInterface</hardwareInterface>
        </joint>
        <actuator name="left_finger_motor">
            <hardwareInterface>hardware_interface/EffortJointInterface</hardwareInterface>
            <mechanicalReduction>1</mechanicalReduction>
        </actuator>
    </transmission>

    <!-- Plugin to link Gazebo and ROS -->
    <gazebo>
        <plugin name="gazebo_ros_control" filename="libgazebo_ros_control.so">
            <robotNamespace>/</robotNamespace>
        </plugin>
    </gazebo>

    <!-- Link1 -->
    <gazebo reference="link_1">
      <mu1>0.2</mu1>
      <mu2>0.2</mu2>
    </gazebo>

    <!-- Link2 -->
    <gazebo reference="link_2">
      <mu1>0.2</mu1>
      <mu2>0.2</mu2>
    </gazebo>

    <!-- Link3 -->
    <gazebo reference="link_3">
      <mu1>0.2</mu1>
      <mu2>0.2</mu2>
    </gazebo>

    <!-- Link4 -->
    <gazebo reference="link_4">
      <mu1>0.2</mu1>
      <mu2>0.2</mu2>
    </gazebo>

    <!-- Link5 -->
    <gazebo reference="link_5">
      <mu1>0.2</mu1>
      <mu2>0.2</mu2>
    </gazebo>

    <!-- Link6 -->
    <gazebo reference="link_6">
      <mu1>0.2</mu1>
      <mu2>0.2</mu2>
    </gazebo>

    <!-- Right Finger Link -->
    <gazebo reference="link_right_finger">
      <mu1>10</mu1>
      <mu2>10</mu2>
      <minDepth>0.001</minDepth>
      <maxVel>0.1</maxVel>
      <kp>100000000.0</kp>
      <kd>1000000.0</kd>
    </gazebo>

    <!-- Left Finger Link -->
    <gazebo reference="link_left_finger">
      <mu1>10</mu1>
      <mu2>10</mu2>
      <minDepth>0.001</minDepth>
      <maxVel>0.1</maxVel>
      <kp>100000000.0</kp>
      <kd>1000000.0</kd>
    </gazebo>

  </xacro:macro>
</robot>
